Workbook

Sheet Resumen
B2: Modelo financiero — Subasta SUB-JA-2026-265709
B3: Plaza de aparcamiento para moto nº 10 · C/ Virtud 38 – C/ Constancia 71 · López de Gomara (Triana), Sevilla
B4: Escenario activo: | C4: =NombreEscenario -> Base | E4: Estrategia principal: | F4: =NombreEstrategia -> Compraventa (reventa) | H4: Cambiar en Supuestos (F7 y F9)
B6: La subasta | E6: Precio de compra (escenario activo)
B7: Valor de subasta (= tasación) | C7: =ValorSubasta -> 7078.45 | E7: Puja (precio de remate) | F7: =Puja -> 5500
B8: Depósito para pujar (5%) | C8: =Deposito -> 353.9225 | E8: Puja / valor de subasta | F8: =Puja/ValorSubasta -> 0.77700627
B9: 70% del valor (aprobación directa) | C9: =UmbralSetenta -> 4954.915 | E9: Impuesto de adquisición | F9: =ImpuestoAdq -> 495.4915
B10: 50% del valor | C10: =UmbralCincuenta -> 3539.225 | E10: Costes fijos (registro, gestoría, deudas, posesión) | F10: =CostesFijosAdq -> 1020
B11: Cantidad reclamada por la Comunidad | C11: =CantidadReclamada -> 10083.73 | E11: Inversión total — compraventa | F11: =FlipInversion -> 7082.1582
B12: Cargas anteriores que asume el comprador | C12: =CargasAnteriores -> 0 | E12: Inversión total — alquiler | F12: =AlqInversion -> 7042.1582
B13: Superficie construida / útil (m²) | C13: =SupConstruida&" / "&SupUtil -> 9.5 / 3.75 | E13: Sobrecoste si tributa por IVA en vez de ITP | F13: =ImpactoIVA -> 659.5085
B14: Fecha de cierre (estimada, verificar) | C14: =FechaCierre -> 46315 | E14: Régimen art. 670 LEC de la puja | F14: =IF(Puja>=UmbralSetenta,"Aprobación directa",IF(Puja>=UmbralCincuenta,"Mejorable (10 + 5 días)","Decide el LAJ")) -> Aprobación directa
B16: Estrategia 1 — Compraventa | E16: Estrategia 2 — Alquiler
B17: Precio de cierre esperado | C17: =PrecioCierre -> 9500 | E17: Renta de mercado (€/mes) | F17: =Renta -> 45
B18: Ingreso neto por la venta | C18: =FlipVentaNeta -> 9085.15 | E18: Renta neta de IVA (€/mes) | F18: =RentaNeta -> 37.190083
B19: Beneficio antes de impuestos | C19: =FlipBAI -> 2002.9918 | E19: NOI año 1 | F19: =AlqNOI -> 242.36694
B20: Beneficio neto | C20: =FlipNeto -> 1622.4234 | E20: Rentabilidad bruta | F20: =AlqRentBruta -> 0.063372759
B21: ROI antes de impuestos | C21: =FlipROI -> 0.28282224 | E21: Rentabilidad neta | F21: =AlqRentNeta -> 0.034416572
B22: TIR anual antes de impuestos | C22: =FlipTIR -> 0.582395 | E22: TIR a 10 años (con venta) | F22: =AlqTIR -> 0.077364815
B23: Plazo (meses) | C23: =MesVenta -> 8 | E23: VAN a la tasa de descuento | F23: =AlqVAN -> 1080.8073
B25: Puja máxima | E25: Escenarios (beneficio y ROI de la compraventa)
B26: Puja mínima prudente (70% del valor) | C26: =PujaMinPrudente -> 4955 | E26: Pesimista — beneficio / ROI | F26: =EscBAI_P -> -2862.5467
B27: Puja máxima — compraventa (ROI objetivo) | C27: =PujaMaxFlip -> 5988.8002 | F27: =EscROI_P -> -0.28295354
B28: Puja máxima — alquiler (rentabilidad objetivo) | C28: =PujaMaxAlq -> 3305.1807 | E28: Base — beneficio / ROI | F28: =EscBAI_B -> 2002.9918
B29: Puja de equilibrio — compraventa (beneficio 0) | C29: =PujaEquilibrio -> 7475.2181 | F29: =EscROI_B -> 0.28282224
B30: Puja máxima recomendada (estrategia principal) | C30: =PujaMaxSel -> 5988.8002 | E30: Optimista — beneficio / ROI | F30: =EscBAI_O -> 4682.0218
F31: =EscROI_O -> 0.75102712
B33: Veredicto sobre la puja del escenario activo
B34: =IF(Puja<UmbralSetenta,"ATENCIÓN: la puja es inferior al 70% del valor de subasta. La Comunidad ejecutante podría adjudicarse la plaza (art. 670.4 LEC).",IF(Puja>PujaMaxSel,"NO RECOMENDADA: la puja supera la puja máxima y no alcanza la rentabilidad objetivo de la estrategia principal.","RECOMENDADA: la puja está entre el 70% del valor de subasta y la puja máxima de la estrategia principal.")) -> RECOMENDADA: la puja está entre el 70% del valor de subasta y la puja máxima de la estrategia principal.
B35: Rango de puja recomendado: | C35: =PujaMinPrudente -> 4955 | D35: a | E35: =MAX(PujaMinPrudente,PujaMaxSel) -> 5988.8002 | F35: =IF(PujaMaxSel<PujaMinPrudente,"La puja máxima no llega al 70%: no pujar","")
B36: Controles del modelo: | C36: =IF(AND(FlipControl="OK",AlqControl="OK"),"OK","REVISAR") -> OK
B38: Alertas clave
B39: 1. La plaza solo admite una moto (3,75 m² útiles): limita la demanda de reventa y de alquiler.
B40: 2. Hay que pujar al menos el 70% del valor (4.954,92 €); por debajo, la Comunidad ejecutante, a la que se deben 10.083,73 €, puede adjudicársela.
B41: 3. Riesgo fiscal: si la adjudicación es una 'primera entrega' del promotor, tributa por IVA 21% en lugar de ITP 7%.
B42: 4. Las cuotas de comunidad impagadas (año en curso y 3 anteriores) y el IBI pendiente pasan al comprador: pedir certificados antes de pujar.
B43: 5. Pendiente de la ficha del Portal: fecha exacta de cierre, tramos entre pujas, pujas actuales y subastas relacionadas.
B45: Cifras en euros. Celdas verdes = vínculos a otras hojas; los supuestos se editan en la hoja Supuestos.

Sheet Subasta
B2: Datos de la subasta y del bien
B3: Extraídos de los documentos del expediente (edicto, certificación registral, decreto y diligencia de valoración).
B5: Campo | C5: Dato | D5: Fuente | E5: Estado
B6: Identificación de la subasta
B7: Identificador | C7: SUB-JA-2026-265709 | D7: Portal de Subastas del BOE | E7: Verificado
B8: Tipo de subasta | C8: Judicial — vía de apremio (ejecución de títulos judiciales) | D8: Doc. 1 — Edicto | E8: Verificado
B9: Órgano gestor | C9: Juzgado de Primera Instancia nº 4 de Sevilla · C/ Vermondo Resta s/n, 41018 | D9: Doc. 1 | E9: Verificado
B10: Procedimiento | C10: Ejecución de títulos judiciales 1455/2022 · Negociado 2E · NIG 4109142120190033606 | D10: Doc. 1 | E10: Verificado
B11: Ejecutante | C11: Comunidad de Propietarios Calle Virtud 44 | D11: Doc. 1 | E11: Verificado
B12: Ejecutado (titular registral) | C12: SUPERCHINDO, S.L. (CIF B92548411) | D12: Docs. 1 y 2 | E12: Verificado
B13: Fecha del edicto | C13: 45824 | D13: Doc. 1 | E13: Verificado
B14: Fecha de cierre de la subasta | C14: =FechaCierre -> 46315 | D14: No figura en los PDF · estimada | E14: PENDIENTE
B15: Lotes | C15: Lote único | D15: Doc. 1 | E15: Verificado
B16: Cantidades reclamadas
B17: Principal reclamado (edicto) | C17: 5130.01 | D17: Doc. 1 — Edicto (16/06/2025) | E17: Verificado
B18: Intereses y costas presupuestados | C18: 4953.72 | D18: Doc. 1 | E18: Verificado
B19: Total reclamado | C19: =C17+C18 -> 10083.73 | D19: Cálculo
B20: Embargo anotado (letra A, 30/12/2022) | C20: 6.476,23 € de principal + 4.150,93 € de intereses y costas | D20: Doc. 2 — Certificación registral | E20: Verificado
B21: Mandamiento de certificación (15/03/2023) | C21: 13.836,42 € de principal + 4.150,93 € de intereses y costas | D21: Doc. 2 | E21: Verificado
B22: Descripción del bien
B23: Tipo de bien | C23: Plaza de aparcamiento nº 10 en planta sótano (apta para moto) | D23: Docs. 1, 2, 4 y 5 | E23: Verificado
B24: Dirección | C24: C/ Virtud 38 y C/ Constancia 71 (acceso por C/ Constancia), Sevilla | D24: Doc. 2 | E24: Verificado
B25: Barrio / código postal | C25: López de Gomara (Triana) · 41010 | D25: Idealista / RealAdvisor | E25: Fuente externa
B26: Superficie construida (m²) | C26: 9.5 | D26: Doc. 2 — Certificación registral | E26: Verificado
B27: Superficie útil (m²) | C27: 3.75 | D27: Doc. 2 (el edicto solo cita la construida) | E27: Verificado
B28: Linderos | C28: Frente: zona de maniobra · Izquierda: trastero nº 17 · Fondo: casa nº 69 de C/ Constancia · Derecha: zona de maniobra | D28: Doc. 2 | E28: Verificado
B29: Cuota de participación en la comunidad | C29: 0.00562 | D29: Doc. 2 | E29: Verificado
B30: Finca registral | C30: Nº 37.841 de Sevilla · Registro de la Propiedad nº 2 · Tomo 1.844, Libro 1.175, Folio 181 | D30: Doc. 2 | E30: Verificado
B31: IDUFIR | C31: 41028000513716 | D31: Doc. 2 | E31: Verificado
B32: Título del ejecutado | C32: División horizontal, escritura de 12/06/2018 (protocolo 1503); inscripción 1ª de 16/11/2018 | D32: Doc. 2 | E32: Verificado
B33: Referencia catastral | C33: No consta en los documentos | D33: Sede Electrónica del Catastro | E33: PENDIENTE
B34: Valoración y condiciones económicas
B35: Valoración pericial definitiva | C35: 7078.45 | D35: Doc. 4 — Decreto 19/03/2025 (sin alegaciones) | E35: Verificado
B36: Cargas anteriores deducidas | C36: 0 | D36: Doc. 5 — Diligencia 19/03/2025 | E36: Verificado
B37: Valor de subasta | C37: 7078.45 | D37: Doc. 5 — Diligencia 19/03/2025 · Doc. 1 | E37: Verificado
B38: Valor de subasta por m² construido | C38: =C37/C26 -> 745.1 | D38: Cálculo
B39: Depósito para pujar (5%) | C39: =Deposito -> 353.9225 | D39: Art. 669.1 LEC | E39: Calculado
B40: 70% del valor de subasta | C40: =UmbralSetenta -> 4954.915 | D40: Art. 670 LEC | E40: Calculado
B41: 50% del valor de subasta | C41: =UmbralCincuenta -> 3539.225 | D41: Art. 670.4 LEC | E41: Calculado
B42: Puja mínima | C42: Sin puja mínima (rige el art. 670 LEC) | D42: Doc. 1, condición particular 3ª | E42: Verificado
...

Sheet Supuestos
B2: Supuestos del modelo — Subasta SUB-JA-2026-265709
B3: Plaza de aparcamiento (moto) nº 10 · C/ Virtud 38 – C/ Constancia 71 · López de Gomara (Triana), Sevilla
B4: Leyenda: | C4: Entrada | D4: Fórmula | E4: Vínculo | F4: Clave / verificar | H4: Solo se editan las celdas azules. La columna F contiene siempre el valor que usa el modelo.
B6: 1. Selección de escenario y estrategia
B7: Escenario activo (1 = Pesimista · 2 = Base · 3 = Optimista) | F7: 2 | G7: nº | H7: Cambia todas las variables de la tabla 2 a la vez.
B8: Nombre del escenario | F8: =CHOOSE(Escenario,"Pesimista","Base","Optimista") -> Base
B9: Estrategia principal (1 = Compraventa · 2 = Alquiler) | F9: 1 | G9: nº | H9: Determina la puja máxima recomendada en el Resumen.
B10: Nombre de la estrategia | F10: =CHOOSE(Estrategia,"Compraventa (reventa)","Alquiler (patrimonial)") -> Compraventa (reventa)
B12: 2. Variables por escenario
B13: Variable | C13: Pesimista | D13: Base | E13: Optimista | F13: Activo | G13: Unidad | H13: Justificación / fuente
B14: Puja (precio de remate) | C14: 6500 | D14: 5500 | E14: 5000 | F14: =INDEX(C14:E14,Escenario) -> 5500 | G14: € | H14: Base 77,7% del valor de subasta (> umbral 70% del art. 670 LEC). Ver hoja 'Puja máxima'.
B15: Precio de salida a la venta | C15: 8000 | D15: 10000 | E15: 12000 | F15: =INDEX(C15:E15,Escenario) -> 10000 | G15: € | H15: Mediana oferta plazas de moto Triana/Remedios 11.900 €; mismo edificio 10.000 € (hoja Comparables).
B16: Renta mensual de mercado (lo que paga el inquilino) | C16: 35 | D16: 45 | E16: 50 | F16: =INDEX(C16:E16,Escenario) -> 45 | G16: €/mes | H16: Comparables Triana: 40–55 €/mes; C/ Ardilla 28 (mismo barrio) 40 €/mes.
B17: Mes de toma de posesión (desde el cierre) | C17: 6 | D17: 4 | E17: 3 | F17: =INDEX(C17:E17,Escenario) -> 4 | G17: mes | H17: Situación posesoria 'no consta'. Pesimista: ocupada y posesión por art. 675 LEC.
B18: Coste de toma de posesión | C18: 800 | D18: 100 | E18: 60 | F18: =INDEX(C18:E18,Escenario) -> 100 | G18: € | H18: Mando/llave del garaje; pesimista incluye abogado y procurador para el lanzamiento.
B19: Cuota de comunidad | C19: 15 | D19: 10 | E19: 8 | F19: =INDEX(C19:E19,Escenario) -> 10 | G19: €/mes | H19: Estimación con cuota de participación 0,562%. Pedir certificado al administrador.
B20: Meses de cuotas impagadas a cargo del adjudicatario | C20: 46 | D20: 36 | E20: 12 | F20: =INDEX(C20:E20,Escenario) -> 36 | G20: meses | H20: Afección real: año en curso + 3 anteriores (art. 9.1.e LPH). Máx. ≈ 46 meses a oct-2026.
B21: Meses de comercialización hasta la venta | C21: 8 | D21: 4 | E21: 2 | F21: =INDEX(C21:E21,Escenario) -> 4 | G21: meses | H21: Mercado de plazas de moto estrecho; plazos de venta largos.
B22: Régimen fiscal de la adquisición (1 = ITP · 2 = IVA) | C22: 2 | D22: 1 | E22: 1 | F22: =INDEX(C22:E22,Escenario) -> 1 | G22: nº | H22: El titular es una S.L. por división horizontal (2018): riesgo de 'primera entrega' con IVA 21%.
B24: 3. Datos de la subasta (vinculados a la hoja Subasta)
B25: Valor de subasta | F25: =Subasta!C37 -> 7078.45 | G25: € | H25: Diligencia de 19/03/2025 (cargas deducibles 0 €).
B26: Depósito para pujar (% del valor de subasta) | F26: 0.05 | G26: % | H26: Art. 669.1 LEC.
B27: Depósito para pujar | F27: =ValorSubasta*DepositoPct -> 353.9225 | G27: € | H27: Se consigna a través del Portal de Subastas (AEAT).
B28: Umbral de aprobación directa (% del valor) | F28: 0.7 | G28: % | H28: Art. 670.1 LEC.
B29: Umbral de aprobación directa | F29: =ValorSubasta*PctAprobacion -> 4954.915 | G29: € | H29: Puja ≥ este importe: se aprueba el remate al mejor postor.
B30: Umbral mínimo de referencia (% del valor) | F30: 0.5 | G30: % | H30: Art. 670.4 LEC.
B31: Umbral mínimo de referencia | F31: =ValorSubasta*PctMinimo -> 3539.225 | G31: € | H31: Por debajo, el remate queda a criterio del LAJ.
B32: Cantidad reclamada (principal + intereses y costas) | F32: =Subasta!C19 -> 10083.73 | G32: € | H32: Edicto de 16/06/2025.
B34: 4. Fiscalidad de la adquisición
B35: Régimen aplicado | F35: =IF(Regimen=1,"ITP — segunda transmisión","IVA — primera entrega del promotor") -> ITP — segunda transmisión | H35: Se elige en la tabla 2 (por escenario).
B36: Tipo ITP Andalucía (tipo general) | F36: 0.07 | G36: % | H36: Ley 5/2021 de Tributos Cedidos de Andalucía.
B37: Valor de referencia catastral (estimado) | F37: 7078.45 | G37: € | H37: PENDIENTE: consultar en Sede del Catastro. Proxy = valoración pericial. Base ITP = máx(remate; valor de referencia).
B38: Tipo IVA (plaza de garaje no anexa a vivienda) | F38: 0.21 | G38: % | H38: Art. 90 LIVA. También grava la comisión de venta y el alquiler de la plaza.
B39: ¿IVA soportado deducible? (1 = Sí · 0 = No) | F39: 0 | G39: nº | H39: Sí solo si el comprador es empresario y alquila la plaza con IVA.
B40: Base imponible | F40: =IF(Regimen=1,MAX(Puja,ValorReferencia),Puja) -> 7078.45 | G40: €
B41: Impuesto de adquisición | F41: =IF(Regimen=1,TipoITP*MAX(Puja,ValorReferencia),TipoIVA*Puja*(1-IVADeducible)) -> 495.4915 | G41: €
B43: 5. Otros costes de adquisición
B44: Registro de la Propiedad (inscripción + cancelación de anotaciones A y B) | F44: 150 | G44: € | H44: Arancel registral para un valor ≈ 7.000 €.
B45: Gestoría / liquidación de impuestos | F45: 250 | G45: € | H45: IVA incluido.
B46: Abogado y procurador (opcional) | F46: 0 | G46: € | H46: No son obligatorios para pujar como tercero.
...

Sheet Comparables
B2: Comparables de mercado — plazas de moto en Sevilla
B3: Precios de oferta publicados en idealista, consultados el 13/10/2026. Superficie en blanco = no publicada.
B5: A. Venta — plazas de moto en Triana y Los Remedios
B6: Ref. idealista | C6: Ubicación | D6: Barrio | E6: Tipo / capacidad | F6: Sup. (m²) | G6: Precio (€) | H6: €/m² | I6: Observaciones | J6: Enlace
B7: 112744803 | C7: C/ Virtud 44 (acceso por C/ Constancia) | D7: López de Gomara (Triana) | E7: Moto · 1 plaza | F7: 4 | G7: 10000 | H7: =IF(F7>0,G7/F7,"") -> 2500 | I7: MISMO EDIFICIO y misma superficie registral (9,50 m² const.): puede ser esta misma finca. Particular; posesión 'a partir de noviembre'. No es un comparable independiente. | J7: https://www.idealista.com/inmueble/112744803/?utm_medium=generativeAI&utm_campaign=appChatgpt&utm_creation=link&utm_source=idGpt&utm_project=leadGeneration&utm_link=inChat_detail
B8: 104181518 | C8: C/ Troya | D8: Triana | E8: Moto · 2 motos | G8: 13500 | H8: =IF(F8>0,G8/F8,"") | I8: Se puede alquilar. | J8: https://www.idealista.com/inmueble/104181518/?utm_medium=generativeAI&utm_campaign=appChatgpt&utm_creation=link&utm_source=idGpt&utm_project=leadGeneration&utm_link=inChat_detail
B9: 102202705 | C9: C/ Virgen de la Estrella 10 | D9: Los Remedios | E9: Moto · 1 plaza | F9: 3 | G9: 11900 | H9: =IF(F9>0,G9/F9,"") -> 3966.6667 | I9: Rampa, puerta automática. | J9: https://www.idealista.com/inmueble/102202705/?utm_medium=generativeAI&utm_campaign=appChatgpt&utm_creation=link&utm_source=idGpt&utm_project=leadGeneration&utm_link=inChat_detail
F10: Nº de comparables | G10: =COUNT(G7:G9) -> 3
F11: Media | G11: =AVERAGE(G7:G9) -> 11800
F12: Mediana | G12: =MEDIAN(G7:G9) -> 11900
F13: Mínimo | G13: =MIN(G7:G9) -> 10000
F14: Máximo | G14: =MAX(G7:G9) -> 13500
B16: B. Venta — plazas de moto en el resto de Sevilla capital
B17: Ref. idealista | C17: Ubicación | D17: Barrio | E17: Tipo / capacidad | F17: Sup. (m²) | G17: Precio (€) | H17: €/m² | I17: Observaciones | J17: Enlace
B18: 112644449 | C18: C/ Francos | D18: Centro (Alfalfa) | E18: Moto · 1,83 × 2,10 m | F18: 3.84 | G18: 16000 | H18: =IF(F18>0,G18/F18,"") -> 4166.6667 | I18: Planta -1, zona sin aparcamiento. | J18: https://www.idealista.com/inmueble/112644449/?utm_medium=generativeAI&utm_campaign=appChatgpt&utm_creation=link&utm_source=idGpt&utm_project=leadGeneration&utm_link=inChat_detail
B19: 112732191 | C19: C/ Juan Antonio Cavestany 20 | D19: Santa Justa | E19: Moto o Smart · 4,40 × 2,10 m | F19: 10 | G19: 15000 | H19: =IF(F19>0,G19/F19,"") -> 1500 | J19: https://www.idealista.com/inmueble/112732191/?utm_medium=generativeAI&utm_campaign=appChatgpt&utm_creation=link&utm_source=idGpt&utm_project=leadGeneration&utm_link=inChat_detail
B20: 111806571 | C20: C/ Mendigorría 5 | D20: Alameda – San Lorenzo | E20: Moto · 1 plaza | G20: 18000 | H20: =IF(F20>0,G20/F20,"") | I20: Vigilancia 24 h. | J20: https://www.idealista.com/inmueble/111806571/?utm_medium=generativeAI&utm_campaign=appChatgpt&utm_creation=link&utm_source=idGpt&utm_project=leadGeneration&utm_link=inChat_detail
B21: 112521156 | C21: C/ Conde Negro 15 | D21: Puerta Carmona | E21: 2 motos | G21: 12250 | H21: =IF(F21>0,G21/F21,"") | I21: Alquilada a 70 €/mes. | J21: https://www.idealista.com/inmueble/112521156/?utm_medium=generativeAI&utm_campaign=appChatgpt&utm_creation=link&utm_source=idGpt&utm_project=leadGeneration&utm_link=inChat_detail
B22: 111834117 | C22: Parqueflores VI Fase | D22: Los Carteros – San Diego | E22: 2–3 motos · 4,50 × 2,20 m | F22: 9.9 | G22: 16000 | H22: =IF(F22>0,G22/F22,"") -> 1616.1616 | J22: https://www.idealista.com/inmueble/111834117/?utm_medium=generativeAI&utm_campaign=appChatgpt&utm_creation=link&utm_source=idGpt&utm_project=leadGeneration&utm_link=inChat_detail
B23: 100622617 | C23: C/ Marqués del Nervión 1 | D23: Nervión | E23: Motos / Smart (se venden juntas) | F23: 6 | G23: 15500 | H23: =IF(F23>0,G23/F23,"") -> 2583.3333 | J23: https://www.idealista.com/inmueble/100622617/?utm_medium=generativeAI&utm_campaign=appChatgpt&utm_creation=link&utm_source=idGpt&utm_project=leadGeneration&utm_link=inChat_detail
B24: 105263661 | C24: C/ Almenas 55 | D24: Bellavista | E24: 4 motos · 14,5 m² útiles | F24: 14.5 | G24: 13000 | H24: =IF(F24>0,G24/F24,"") -> 896.55172 | I24: Alquiladas; anuncia rentabilidad del 8%. | J24: https://www.idealista.com/inmueble/105263661/?utm_medium=generativeAI&utm_campaign=appChatgpt&utm_creation=link&utm_source=idGpt&utm_project=leadGeneration&utm_link=inChat_detail
B25: 109368921 | C25: C/ Marathón | D25: Avenida de las Ciencias | E25: Moto · 12 m² | F25: 12 | G25: 14500 | H25: =IF(F25>0,G25/F25,"") -> 1208.3333 | I25: Venta directa de promotora (impuestos aparte). | J25: https://www.idealista.com/inmueble/109368921/?utm_medium=generativeAI&utm_campaign=appChatgpt&utm_creation=link&utm_source=idGpt&utm_project=leadGeneration&utm_link=inChat_detail
B26: 107119263 | C26: C/ Luis Montoto 63 | D26: Santa Justa | E26: Moto · 1 plaza | G26: 8200 | H26: =IF(F26>0,G26/F26,"") | I26: Opción de 3 plazas por 24.000 €. | J26: https://www.idealista.com/inmueble/107119263/?utm_medium=generativeAI&utm_campaign=appChatgpt&utm_creation=link&utm_source=idGpt&utm_project=leadGeneration&utm_link=inChat_detail
B27: 112181517 | C27: C/ Monzón 1 D | D27: Heliópolis | E27: 2–3 motos | G27: 8000 | H27: =IF(F27>0,G27/F27,"") | I27: Concesión administrativa (70 años). | J27: https://www.idealista.com/inmueble/112181517/?utm_medium=generativeAI&utm_campaign=appChatgpt&utm_creation=link&utm_source=idGpt&utm_project=leadGeneration&utm_link=inChat_detail
B28: 105870147 | C28: C/ Fernández de Ribera | D28: Nervión | E28: 2–3 motos | G28: 7000 | H28: =IF(F28>0,G28/F28,"") | I28: Planta -3, acceso complicado. | J28: https://www.idealista.com/inmueble/105870147/?utm_medium=generativeAI&utm_campaign=appChatgpt&utm_creation=link&utm_source=idGpt&utm_project=leadGeneration&utm_link=inChat_detail
B29: 111785329 | C29: C/ Hispano Aviación 2 | D29: Tablada | E29: Moto · 1 plaza | G29: 5000 | H29: =IF(F29>0,G29/F29,"") | I29: Alquilable a 30 €/mes. | J29: https://www.idealista.com/inmueble/111785329/?utm_medium=generativeAI&utm_campaign=appChatgpt&utm_creation=link&utm_source=idGpt&utm_project=leadGeneration&utm_link=inChat_detail
B30: 106975276 | C30: C/ Hispano Aviación 2 | D30: Tablada | E30: Moto · 1 plaza | G30: 4500 | H30: =IF(F30>0,G30/F30,"") | J30: https://www.idealista.com/inmueble/106975276/?utm_medium=generativeAI&utm_campaign=appChatgpt&utm_creation=link&utm_source=idGpt&utm_project=leadGeneration&utm_link=inChat_detail
B31: 29257022 | C31: C/ Electricidad 5 | D31: Santa Aurelia | E31: 2 motos | G31: 5000 | H31: =IF(F31>0,G31/F31,"") | J31: https://www.idealista.com/inmueble/29257022/?utm_medium=generativeAI&utm_campaign=appChatgpt&utm_creation=link&utm_source=idGpt&utm_project=leadGeneration&utm_link=inChat_detail
F32: Nº de comparables | G32: =COUNT(G18:G31) -> 14
F33: Media | G33: =AVERAGE(G18:G31) -> 11282.143
F34: Mediana | G34: =MEDIAN(G18:G31) -> 12625
F35: Mínimo | G35: =MIN(G18:G31) -> 4500
F36: Máximo | G36: =MAX(G18:G31) -> 18000
B38: C. Alquiler — plazas de moto en Triana
B39: Ref. idealista | C39: Ubicación | D39: Barrio | E39: Tipo / capacidad | F39: Sup. (m²) | G39: Precio (€/mes) | H39: €/mes/m² | I39: Observaciones | J39: Enlace
B40: 82917753 | C40: C/ Ardilla 28 | D40: López de Gomara (Triana) | E40: Moto | G40: 40 | H40: =IF(F40>0,G40/F40,"") | I40: El comparable más cercano (mismo barrio). | J40: https://www.idealista.com/inmueble/82917753/?utm_medium=generativeAI&utm_campaign=appChatgpt&utm_creation=link&utm_source=idGpt&utm_project=leadGeneration&utm_link=inChat_detail
B41: 89222824 | C41: C/ Pagés del Corro 82 | D41: Ronda de Triana – Patrocinio | E41: Moto | G41: 40 | H41: =IF(F41>0,G41/F41,"") | I41: Cámaras, puerta automática. | J41: https://www.idealista.com/inmueble/89222824/?utm_medium=generativeAI&utm_campaign=appChatgpt&utm_creation=link&utm_source=idGpt&utm_project=leadGeneration&utm_link=inChat_detail
B42: 96520950 | C42: C/ Doctores Lasso Simarro | D42: Betis – Pagés del Corro | E42: Moto | G42: 40 | H42: =IF(F42>0,G42/F42,"") | I42: Acceso por elevador. | J42: https://www.idealista.com/inmueble/96520950/?utm_medium=generativeAI&utm_campaign=appChatgpt&utm_creation=link&utm_source=idGpt&utm_project=leadGeneration&utm_link=inChat_detail
B43: 111286433 | C43: C/ Alfarería 124 | D43: Betis – Pagés del Corro | E43: Moto (parking profesional) | G43: 49 | H43: =IF(F43>0,G43/F43,"") | I43: 24/7, taquilla y seguro incluidos. | J43: https://www.idealista.com/inmueble/111286433/?utm_medium=generativeAI&utm_campaign=appChatgpt&utm_creation=link&utm_source=idGpt&utm_project=leadGeneration&utm_link=inChat_detail
B44: 84436084 | C44: C/ Castilla 83 | D44: Betis – Pagés del Corro | E44: Moto | G44: 50 | H44: =IF(F44>0,G44/F44,"") | J44: https://www.idealista.com/inmueble/84436084/?utm_medium=generativeAI&utm_campaign=appChatgpt&utm_creation=link&utm_source=idGpt&utm_project=leadGeneration&utm_link=inChat_detail
...

Sheet Compraventa
B2: Estrategia 1 — Compraventa (adjudicación y reventa)
B3: Flujo de caja mensual desde el cierre de la subasta. Todas las cifras en euros.
B4: Escenario activo: | C4: =NombreEscenario -> Base
B6: Indicadores
B7: Puja (precio de remate) | C7: =Puja -> 5500 | E7: Notas
B8: Impuesto de adquisición | C8: =ImpuestoAdq -> 495.4915 | E8: • El depósito se consigna al pujar; si no se gana la subasta se devuelve íntegro.
B9: Costes fijos de adquisición | C9: =CostesFijosAdq -> 1020 | E9: • El impuesto de adquisición se liquida tras el decreto de adjudicación (30 días hábiles).
B10: Coste de tenencia | C10: =CosteTenenciaFlip -> 66.666667 | E10: • Las deudas afectas de comunidad e IBI se pagan al tomar posesión para regularizar la plaza.
B11: Inversión total | C11: =-SUM(C31:C37) -> 7082.1582 | E11: • El impuesto sobre la ganancia se imputa en el mes de venta (simplificación: se paga en la renta del año siguiente).
B12: Ingreso neto por la venta | C12: =C38 -> 9085.15 | E12: • La TIR es mensual anualizada sobre los flujos de la tabla inferior.
B13: Beneficio antes de impuestos | C13: =C39 -> 2002.9918
B14: Impuesto sobre la ganancia | C14: =C40 -> -380.56845
B15: Beneficio neto | C15: =C41 -> 1622.4234
B16: ROI antes de impuestos | C16: =IF(C11>0,C13/C11,0) -> 0.28282224
B17: ROI neto | C17: =IF(C11>0,C15/C11,0) -> 0.22908601
B18: Múltiplo sobre el capital (MOIC neto) | C18: =IF(C11>0,(C11+C15)/C11,0) -> 1.229086
B19: Plazo total (meses) | C19: =MesVenta -> 8
B20: TIR anual antes de impuestos | C20: =(1+IRR(D39:AA39,0.02))^12-1 -> 0.582395
B21: TIR anual neta | C21: =(1+IRR(D41:AA41,0.02))^12-1 -> 0.46277117
B22: Exposición máxima de caja | C22: =-MIN(D42:AA42) -> 7068.8248
B23: Control: fórmula cerrada = flujo mensual | C23: =IF(ABS(C13-(VentaNeta-Puja-ImpuestoAdq-CostesFijosAdq-CosteTenenciaFlip))<0.01,"OK","REVISAR") -> OK
B24: Control: venta dentro del horizonte modelizado (mes ≤ 23) | C24: =IF(MesVenta<=23,"OK","AMPLIAR HORIZONTE") -> OK
B26: Flujo de caja mensual
B27: Concepto | C27: Total
B28: Mes | D28: 0 | E28: =D28+1 -> 1 | F28: =E28+1 -> 2 | G28: =F28+1 -> 3 | H28: =G28+1 -> 4 | I28: =H28+1 -> 5 | J28: =I28+1 -> 6 | K28: =J28+1 -> 7 | L28: =K28+1 -> 8 | ... AA28: =Z28+1 -> 23
B29: Fecha | D29: =EDATE(FechaCierre,D$28) -> 46315 | E29: =EDATE(FechaCierre,E$28) -> 46346 | F29: =EDATE(FechaCierre,F$28) -> 46376 | G29: =EDATE(FechaCierre,G$28) -> 46407 | H29: =EDATE(FechaCierre,H$28) -> 46438 | I29: =EDATE(FechaCierre,I$28) -> 46466 | J29: =EDATE(FechaCierre,J$28) -> 46497 | K29: =EDATE(FechaCierre,K$28) -> 46527 | ... AA29: =EDATE(FechaCierre,AA$28) -> 47016
B30: Hito | D30: =TRIM(IF(D$28=0,"Subasta ","")&IF(D$28=MesPago,"Pago ","")&IF(D$28=MesDecreto,"Decreto ","")&IF(D$28=MesPosesion,"Posesión ","")&IF(D$28=MesVenta,"Venta","")) -> Subasta | E30: =TRIM(IF(E$28=0,"Subasta ","")&IF(E$28=MesPago,"Pago ","")&IF(E$28=MesDecreto,"Decreto ","")&IF(E$28=MesPosesion,"Posesión ","")&IF(E$28=MesVenta,"Venta","")) -> Pago | F30: =TRIM(IF(F$28=0,"Subasta ","")&IF(F$28=MesPago,"Pago ","")&IF(F$28=MesDecreto,"Decreto ","")&IF(F$28=MesPosesion,"Posesión ","")&IF(F$28=MesVenta,"Venta","")) | G30: =TRIM(IF(G$28=0,"Subasta ","")&IF(G$28=MesPago,"Pago ","")&IF(G$28=MesDecreto,"Decreto ","")&IF(G$28=MesPosesion,"Posesión ","")&IF(G$28=MesVenta,"Venta","")) -> Decreto | H30: =TRIM(IF(H$28=0,"Subasta ","")&IF(H$28=MesPago,"Pago ","")&IF(H$28=MesDecreto,"Decreto ","")&IF(H$28=MesPosesion,"Posesión ","")&IF(H$28=MesVenta,"Venta","")) -> Posesión | I30: =TRIM(IF(I$28=0,"Subasta ","")&IF(I$28=MesPago,"Pago ","")&IF(I$28=MesDecreto,"Decreto ","")&IF(I$28=MesPosesion,"Posesión ","")&IF(I$28=MesVenta,"Venta","")) | J30: =TRIM(IF(J$28=0,"Subasta ","")&IF(J$28=MesPago,"Pago ","")&IF(J$28=MesDecreto,"Decreto ","")&IF(J$28=MesPosesion,"Posesión ","")&IF(J$28=MesVenta,"Venta","")) | K30: =TRIM(IF(K$28=0,"Subasta ","")&IF(K$28=MesPago,"Pago ","")&IF(K$28=MesDecreto,"Decreto ","")&IF(K$28=MesPosesion,"Posesión ","")&IF(K$28=MesVenta,"Venta","")) | ... AA30: =TRIM(IF(AA$28=0,"Subasta ","")&IF(AA$28=MesPago,"Pago ","")&IF(AA$28=MesDecreto,"Decreto ","")&IF(AA$28=MesPosesion,"Posesión ","")&IF(AA$28=MesVenta,"Venta",""))
B31: Depósito (5% del valor de subasta) | C31: =SUM(D31:AA31) -> -353.9225 | D31: =IF(D$28=0,-Deposito,0) -> -353.9225 | E31: =IF(E$28=0,-Deposito,0) -> 0 | F31: =IF(F$28=0,-Deposito,0) -> 0 | G31: =IF(G$28=0,-Deposito,0) -> 0 | H31: =IF(H$28=0,-Deposito,0) -> 0 | I31: =IF(I$28=0,-Deposito,0) -> 0 | J31: =IF(J$28=0,-Deposito,0) -> 0 | K31: =IF(K$28=0,-Deposito,0) -> 0 | ... AA31: =IF(AA$28=0,-Deposito,0) -> 0
B32: Resto del precio de remate | C32: =SUM(D32:AA32) -> -5146.0775 | D32: =IF(D$28=MesPago,-(Puja-Deposito),0) -> 0 | E32: =IF(E$28=MesPago,-(Puja-Deposito),0) -> -5146.0775 | F32: =IF(F$28=MesPago,-(Puja-Deposito),0) -> 0 | G32: =IF(G$28=MesPago,-(Puja-Deposito),0) -> 0 | H32: =IF(H$28=MesPago,-(Puja-Deposito),0) -> 0 | I32: =IF(I$28=MesPago,-(Puja-Deposito),0) -> 0 | J32: =IF(J$28=MesPago,-(Puja-Deposito),0) -> 0 | K32: =IF(K$28=MesPago,-(Puja-Deposito),0) -> 0 | ... AA32: =IF(AA$28=MesPago,-(Puja-Deposito),0) -> 0
B33: Impuesto de adquisición (ITP / IVA) | C33: =SUM(D33:AA33) -> -495.4915 | D33: =IF(D$28=MesDecreto,-ImpuestoAdq,0) -> 0 | E33: =IF(E$28=MesDecreto,-ImpuestoAdq,0) -> 0 | F33: =IF(F$28=MesDecreto,-ImpuestoAdq,0) -> 0 | G33: =IF(G$28=MesDecreto,-ImpuestoAdq,0) -> -495.4915 | H33: =IF(H$28=MesDecreto,-ImpuestoAdq,0) -> 0 | I33: =IF(I$28=MesDecreto,-ImpuestoAdq,0) -> 0 | J33: =IF(J$28=MesDecreto,-ImpuestoAdq,0) -> 0 | K33: =IF(K$28=MesDecreto,-ImpuestoAdq,0) -> 0 | ... AA33: =IF(AA$28=MesDecreto,-ImpuestoAdq,0) -> 0
B34: Registro, gestoría y abogado | C34: =SUM(D34:AA34) -> -400 | D34: =IF(D$28=MesDecreto,-(Registro+Gestoria+Abogado),0) -> 0 | E34: =IF(E$28=MesDecreto,-(Registro+Gestoria+Abogado),0) -> 0 | F34: =IF(F$28=MesDecreto,-(Registro+Gestoria+Abogado),0) -> 0 | G34: =IF(G$28=MesDecreto,-(Registro+Gestoria+Abogado),0) -> -400 | H34: =IF(H$28=MesDecreto,-(Registro+Gestoria+Abogado),0) -> 0 | I34: =IF(I$28=MesDecreto,-(Registro+Gestoria+Abogado),0) -> 0 | J34: =IF(J$28=MesDecreto,-(Registro+Gestoria+Abogado),0) -> 0 | K34: =IF(K$28=MesDecreto,-(Registro+Gestoria+Abogado),0) -> 0 | ... AA34: =IF(AA$28=MesDecreto,-(Registro+Gestoria+Abogado),0) -> 0
B35: Deudas afectas (comunidad + IBI) | C35: =SUM(D35:AA35) -> -520 | D35: =IF(D$28=MesPosesion,-(DeudaComunidad+DeudaIBI),0) -> 0 | E35: =IF(E$28=MesPosesion,-(DeudaComunidad+DeudaIBI),0) -> 0 | F35: =IF(F$28=MesPosesion,-(DeudaComunidad+DeudaIBI),0) -> 0 | G35: =IF(G$28=MesPosesion,-(DeudaComunidad+DeudaIBI),0) -> 0 | H35: =IF(H$28=MesPosesion,-(DeudaComunidad+DeudaIBI),0) -> -520 | I35: =IF(I$28=MesPosesion,-(DeudaComunidad+DeudaIBI),0) -> 0 | J35: =IF(J$28=MesPosesion,-(DeudaComunidad+DeudaIBI),0) -> 0 | K35: =IF(K$28=MesPosesion,-(DeudaComunidad+DeudaIBI),0) -> 0 | ... AA35: =IF(AA$28=MesPosesion,-(DeudaComunidad+DeudaIBI),0) -> 0
B36: Toma de posesión | C36: =SUM(D36:AA36) -> -100 | D36: =IF(D$28=MesPosesion,-CostePosesion,0) -> 0 | E36: =IF(E$28=MesPosesion,-CostePosesion,0) -> 0 | F36: =IF(F$28=MesPosesion,-CostePosesion,0) -> 0 | G36: =IF(G$28=MesPosesion,-CostePosesion,0) -> 0 | H36: =IF(H$28=MesPosesion,-CostePosesion,0) -> -100 | I36: =IF(I$28=MesPosesion,-CostePosesion,0) -> 0 | J36: =IF(J$28=MesPosesion,-CostePosesion,0) -> 0 | K36: =IF(K$28=MesPosesion,-CostePosesion,0) -> 0 | ... AA36: =IF(AA$28=MesPosesion,-CostePosesion,0) -> 0
B37: Gastos corrientes (comunidad, IBI, seguro) | C37: =SUM(D37:AA37) -> -66.666667 | D37: =IF(AND(D$28>MesDecreto,D$28<=MesVenta),-GastoMensual,0) -> 0 | E37: =IF(AND(E$28>MesDecreto,E$28<=MesVenta),-GastoMensual,0) -> 0 | F37: =IF(AND(F$28>MesDecreto,F$28<=MesVenta),-GastoMensual,0) -> 0 | G37: =IF(AND(G$28>MesDecreto,G$28<=MesVenta),-GastoMensual,0) -> 0 | H37: =IF(AND(H$28>MesDecreto,H$28<=MesVenta),-GastoMensual,0) -> -13.333333 | I37: =IF(AND(I$28>MesDecreto,I$28<=MesVenta),-GastoMensual,0) -> -13.333333 | J37: =IF(AND(J$28>MesDecreto,J$28<=MesVenta),-GastoMensual,0) -> -13.333333 | K37: =IF(AND(K$28>MesDecreto,K$28<=MesVenta),-GastoMensual,0) -> -13.333333 | ... AA37: =IF(AND(AA$28>MesDecreto,AA$28<=MesVenta),-GastoMensual,0) -> 0
B38: Ingreso neto por la venta | C38: =SUM(D38:AA38) -> 9085.15 | D38: =IF(D$28=MesVenta,VentaNeta,0) -> 0 | E38: =IF(E$28=MesVenta,VentaNeta,0) -> 0 | F38: =IF(F$28=MesVenta,VentaNeta,0) -> 0 | G38: =IF(G$28=MesVenta,VentaNeta,0) -> 0 | H38: =IF(H$28=MesVenta,VentaNeta,0) -> 0 | I38: =IF(I$28=MesVenta,VentaNeta,0) -> 0 | J38: =IF(J$28=MesVenta,VentaNeta,0) -> 0 | K38: =IF(K$28=MesVenta,VentaNeta,0) -> 0 | ... AA38: =IF(AA$28=MesVenta,VentaNeta,0) -> 0
B39: Flujo antes de impuestos | C39: =SUM(C31:C38) -> 2002.9918 | D39: =SUM(D31:D38) -> -353.9225 | E39: =SUM(E31:E38) -> -5146.0775 | F39: =SUM(F31:F38) -> 0 | G39: =SUM(G31:G38) -> -895.4915 | H39: =SUM(H31:H38) -> -633.33333 | I39: =SUM(I31:I38) -> -13.333333 | J39: =SUM(J31:J38) -> -13.333333 | ... AA39: =SUM(AA31:AA38) -> 0
B40: Impuesto sobre la ganancia | C40: =SUM(D40:AA40) -> -380.56845 | D40: =IF(D$28=MesVenta,-MAX(0,$C$39)*TipoGanancia,0) -> 0 | E40: =IF(E$28=MesVenta,-MAX(0,$C$39)*TipoGanancia,0) -> 0 | F40: =IF(F$28=MesVenta,-MAX(0,$C$39)*TipoGanancia,0) -> 0 | G40: =IF(G$28=MesVenta,-MAX(0,$C$39)*TipoGanancia,0) -> 0 | H40: =IF(H$28=MesVenta,-MAX(0,$C$39)*TipoGanancia,0) -> 0 | I40: =IF(I$28=MesVenta,-MAX(0,$C$39)*TipoGanancia,0) -> 0 | J40: =IF(J$28=MesVenta,-MAX(0,$C$39)*TipoGanancia,0) -> 0 | K40: =IF(K$28=MesVenta,-MAX(0,$C$39)*TipoGanancia,0) -> 0 | ... AA40: =IF(AA$28=MesVenta,-MAX(0,$C$39)*TipoGanancia,0) -> 0
B41: Flujo después de impuestos | C41: =C39+C40 -> 1622.4234 | D41: =D39+D40 -> -353.9225 | E41: =E39+E40 -> -5146.0775 | F41: =F39+F40 -> 0 | G41: =G39+G40 -> -895.4915 | H41: =H39+H40 -> -633.33333 | I41: =I39+I40 -> -13.333333 | J41: =J39+J40 -> -13.333333 | ... AA41: =AA39+AA40 -> 0
B42: Caja acumulada | D42: =D41 -> -353.9225 | E42: =D42+E41 -> -5500 | F42: =E42+F41 -> -5500 | G42: =F42+G41 -> -6395.4915 | H42: =G42+H41 -> -7028.8248 | I42: =H42+I41 -> -7042.1582 | J42: =I42+J41 -> -7055.4915 | K42: =J42+K41 -> -7068.8248 | L42: =K42+L41 -> 1622.4234 | ... AA42: =Z42+AA41 -> 1622.4234

Sheet Alquiler
B2: Estrategia 2 — Alquiler (patrimonial a 10 años)
B3: Año 0 = desde el cierre de la subasta hasta el inicio del alquiler. Análisis antes de impuestos.
B4: Escenario activo: | C4: =NombreEscenario -> Base
B6: Indicadores
B7: Inversión total | C7: =-D26 -> 7042.1582 | E7: Notas
B8: Renta de mercado (año 1) | C8: =E27 -> 540 | E8: • Alquilar una plaza de garaje independiente obliga a repercutir IVA (21%): la renta de mercado se trata como IVA incluido.
B9: Ingresos netos (año 1) | C9: =E30 -> 410.57851 | E9: • Si el inversor es empresario a efectos de IVA, puede deducir el IVA soportado en la compra (ver Supuestos, sección 4).
B10: NOI (año 1) | C10: =E36 -> 242.36694 | E10: • Análisis antes de impuestos sobre la renta (IRPF / IS) y sin amortización fiscal.
B11: Rentabilidad bruta (renta neta de IVA / inversión) | C11: =IF(C7>0,RentaNeta*12/C7,0) -> 0.063372759 | E11: • El valor de salida aplica la revalorización anual al precio de salida actual y descuenta comisión y plusvalía.
B12: Rentabilidad neta (NOI / inversión) | C12: =IF(C7>0,C10/C7,0) -> 0.034416572
B13: Rentabilidad bruta de anuncio (renta × 12 / puja) | C13: =IF(Puja>0,Renta*12/Puja,0) -> 0.098181818
B14: TIR a 10 años (con venta final) | C14: =IRR(D38:N38,0.05) -> 0.077364815
B15: VAN a la tasa de descuento | C15: =D38+NPV(TasaDescuento,E38:N38) -> 1080.8073
B16: Años para recuperar la inversión (simple) | C16: =IF(C10>0,C7/C10,"n/a") -> 29.05577
B17: Múltiplo sobre el capital (MOIC) | C17: =IF(C7>0,(C7+C38)/C7,0) -> 1.9490341
B18: Control: NOI año 1 = fórmula cerrada | C18: =IF(ABS(C10-NOIInicial)<0.01,"OK","REVISAR") -> OK
B23: Proyección anual
B24: Concepto | C24: Total
B25: Año | D25: 0 | E25: =D25+1 -> 1 | F25: =E25+1 -> 2 | G25: =F25+1 -> 3 | H25: =G25+1 -> 4 | I25: =H25+1 -> 5 | J25: =I25+1 -> 6 | K25: =J25+1 -> 7 | L25: =K25+1 -> 8 | ... N25: =M25+1 -> 10
B26: Inversión inicial (puja + impuestos + costes + tenencia) | C26: =SUM(D26:N26) -> -7042.1582 | D26: =IF(D$25=0,-(Puja+ImpuestoAdq+CostesFijosAdq+CosteTenenciaAlq),0) -> -7042.1582 | E26: =IF(E$25=0,-(Puja+ImpuestoAdq+CostesFijosAdq+CosteTenenciaAlq),0) -> 0 | F26: =IF(F$25=0,-(Puja+ImpuestoAdq+CostesFijosAdq+CosteTenenciaAlq),0) -> 0 | G26: =IF(G$25=0,-(Puja+ImpuestoAdq+CostesFijosAdq+CosteTenenciaAlq),0) -> 0 | H26: =IF(H$25=0,-(Puja+ImpuestoAdq+CostesFijosAdq+CosteTenenciaAlq),0) -> 0 | I26: =IF(I$25=0,-(Puja+ImpuestoAdq+CostesFijosAdq+CosteTenenciaAlq),0) -> 0 | J26: =IF(J$25=0,-(Puja+ImpuestoAdq+CostesFijosAdq+CosteTenenciaAlq),0) -> 0 | K26: =IF(K$25=0,-(Puja+ImpuestoAdq+CostesFijosAdq+CosteTenenciaAlq),0) -> 0 | ... N26: =IF(N$25=0,-(Puja+ImpuestoAdq+CostesFijosAdq+CosteTenenciaAlq),0) -> 0
B27: Renta de mercado (lo que paga el inquilino) | C27: =SUM(D27:N27) -> 6049.8262 | D27: =IF(D$25>=1,Renta*12*(1+CrecRenta)^(D$25-1),0) -> 0 | E27: =IF(E$25>=1,Renta*12*(1+CrecRenta)^(E$25-1),0) -> 540 | F27: =IF(F$25>=1,Renta*12*(1+CrecRenta)^(F$25-1),0) -> 553.5 | G27: =IF(G$25>=1,Renta*12*(1+CrecRenta)^(G$25-1),0) -> 567.3375 | H27: =IF(H$25>=1,Renta*12*(1+CrecRenta)^(H$25-1),0) -> 581.52094 | I27: =IF(I$25>=1,Renta*12*(1+CrecRenta)^(I$25-1),0) -> 596.05896 | J27: =IF(J$25>=1,Renta*12*(1+CrecRenta)^(J$25-1),0) -> 610.96043 | K27: =IF(K$25>=1,Renta*12*(1+CrecRenta)^(K$25-1),0) -> 626.23445 | ... N27: =IF(N$25>=1,Renta*12*(1+CrecRenta)^(N$25-1),0) -> 674.386
B28: IVA repercutido incluido en la renta | C28: =SUM(D28:N28) -> -1049.9698 | D28: =-D27*TipoIVA*RentaInclIVA/(1+TipoIVA*RentaInclIVA) -> 0 | E28: =-E27*TipoIVA*RentaInclIVA/(1+TipoIVA*RentaInclIVA) -> -93.719008 | F28: =-F27*TipoIVA*RentaInclIVA/(1+TipoIVA*RentaInclIVA) -> -96.061983 | G28: =-G27*TipoIVA*RentaInclIVA/(1+TipoIVA*RentaInclIVA) -> -98.463533 | H28: =-H27*TipoIVA*RentaInclIVA/(1+TipoIVA*RentaInclIVA) -> -100.92512 | I28: =-I27*TipoIVA*RentaInclIVA/(1+TipoIVA*RentaInclIVA) -> -103.44825 | J28: =-J27*TipoIVA*RentaInclIVA/(1+TipoIVA*RentaInclIVA) -> -106.03446 | K28: =-K27*TipoIVA*RentaInclIVA/(1+TipoIVA*RentaInclIVA) -> -108.68532 | ... N28: =-N27*TipoIVA*RentaInclIVA/(1+TipoIVA*RentaInclIVA) -> -117.0422
B29: Desocupación e impagos | C29: =SUM(D29:N29) -> -399.98851 | D29: =-(D27+D28)*Desocupacion -> 0 | E29: =-(E27+E28)*Desocupacion -> -35.702479 | F29: =-(F27+F28)*Desocupacion -> -36.595041 | G29: =-(G27+G28)*Desocupacion -> -37.509917 | H29: =-(H27+H28)*Desocupacion -> -38.447665 | I29: =-(I27+I28)*Desocupacion -> -39.408857 | J29: =-(J27+J28)*Desocupacion -> -40.394078 | K29: =-(K27+K28)*Desocupacion -> -41.40393 | ... N29: =-(N27+N28)*Desocupacion -> -44.587504
B30: Ingresos netos | C30: =SUM(D30:N30) -> 4599.8678 | D30: =D27+D28+D29 -> 0 | E30: =E27+E28+E29 -> 410.57851 | F30: =F27+F28+F29 -> 420.84298 | G30: =G27+G28+G29 -> 431.36405 | H30: =H27+H28+H29 -> 442.14815 | I30: =I27+I28+I29 -> 453.20185 | J30: =J27+J28+J29 -> 464.5319 | K30: =K27+K28+K29 -> 476.1452 | ... N30: =N27+N28+N29 -> 512.7563
B31: Comunidad | C31: =SUM(D31:N31) -> -1344.4058 | D31: =IF(D$25>=1,-CuotaComunidad*12*(1+InflGastos)^(D$25-1),0) -> 0 | E31: =IF(E$25>=1,-CuotaComunidad*12*(1+InflGastos)^(E$25-1),0) -> -120 | F31: =IF(F$25>=1,-CuotaComunidad*12*(1+InflGastos)^(F$25-1),0) -> -123 | G31: =IF(G$25>=1,-CuotaComunidad*12*(1+InflGastos)^(G$25-1),0) -> -126.075 | H31: =IF(H$25>=1,-CuotaComunidad*12*(1+InflGastos)^(H$25-1),0) -> -129.22688 | I31: =IF(I$25>=1,-CuotaComunidad*12*(1+InflGastos)^(I$25-1),0) -> -132.45755 | J31: =IF(J$25>=1,-CuotaComunidad*12*(1+InflGastos)^(J$25-1),0) -> -135.76899 | K31: =IF(K$25>=1,-CuotaComunidad*12*(1+InflGastos)^(K$25-1),0) -> -139.16321 | ... N31: =IF(N$25>=1,-CuotaComunidad*12*(1+InflGastos)^(N$25-1),0) -> -149.86356
B32: IBI | C32: =SUM(D32:N32) -> -448.13527 | D32: =IF(D$25>=1,-IBIAnual*(1+InflGastos)^(D$25-1),0) -> 0 | E32: =IF(E$25>=1,-IBIAnual*(1+InflGastos)^(E$25-1),0) -> -40 | F32: =IF(F$25>=1,-IBIAnual*(1+InflGastos)^(F$25-1),0) -> -41 | G32: =IF(G$25>=1,-IBIAnual*(1+InflGastos)^(G$25-1),0) -> -42.025 | H32: =IF(H$25>=1,-IBIAnual*(1+InflGastos)^(H$25-1),0) -> -43.075625 | I32: =IF(I$25>=1,-IBIAnual*(1+InflGastos)^(I$25-1),0) -> -44.152516 | J32: =IF(J$25>=1,-IBIAnual*(1+InflGastos)^(J$25-1),0) -> -45.256329 | K32: =IF(K$25>=1,-IBIAnual*(1+InflGastos)^(K$25-1),0) -> -46.387737 | ... N32: =IF(N$25>=1,-IBIAnual*(1+InflGastos)^(N$25-1),0) -> -49.954519
B33: Seguro | C33: =SUM(D33:N33) -> 0 | D33: =IF(D$25>=1,-SeguroAnual*(1+InflGastos)^(D$25-1),0) -> 0 | E33: =IF(E$25>=1,-SeguroAnual*(1+InflGastos)^(E$25-1),0) -> 0 | F33: =IF(F$25>=1,-SeguroAnual*(1+InflGastos)^(F$25-1),0) -> 0 | G33: =IF(G$25>=1,-SeguroAnual*(1+InflGastos)^(G$25-1),0) -> 0 | H33: =IF(H$25>=1,-SeguroAnual*(1+InflGastos)^(H$25-1),0) -> 0 | I33: =IF(I$25>=1,-SeguroAnual*(1+InflGastos)^(I$25-1),0) -> 0 | J33: =IF(J$25>=1,-SeguroAnual*(1+InflGastos)^(J$25-1),0) -> 0 | K33: =IF(K$25>=1,-SeguroAnual*(1+InflGastos)^(K$25-1),0) -> 0 | ... N33: =IF(N$25>=1,-SeguroAnual*(1+InflGastos)^(N$25-1),0) -> 0
B34: Gestión | C34: =SUM(D34:N34) -> 0 | D34: =-D30*GestionPct -> 0 | E34: =-E30*GestionPct -> 0 | F34: =-F30*GestionPct -> 0 | G34: =-G30*GestionPct -> 0 | H34: =-H30*GestionPct -> 0 | I34: =-I30*GestionPct -> 0 | J34: =-J30*GestionPct -> 0 | K34: =-K30*GestionPct -> 0 | ... N34: =-N30*GestionPct -> 0
B35: Reserva de mantenimiento | C35: =SUM(D35:N35) -> -91.997356 | D35: =-D30*MantenimientoPct -> 0 | E35: =-E30*MantenimientoPct -> -8.2115702 | F35: =-F30*MantenimientoPct -> -8.4168595 | G35: =-G30*MantenimientoPct -> -8.627281 | H35: =-H30*MantenimientoPct -> -8.842963 | I35: =-I30*MantenimientoPct -> -9.0640371 | J35: =-J30*MantenimientoPct -> -9.290638 | K35: =-K30*MantenimientoPct -> -9.522904 | ... N35: =-N30*MantenimientoPct -> -10.255126
B36: Resultado operativo neto (NOI) | C36: =SUM(D36:N36) -> 2715.3294 | D36: =D30+SUM(D31:D35) -> 0 | E36: =E30+SUM(E31:E35) -> 242.36694 | F36: =F30+SUM(F31:F35) -> 248.42612 | G36: =G30+SUM(G31:G35) -> 254.63677 | H36: =H30+SUM(H31:H35) -> 261.00269 | I36: =I30+SUM(I31:I35) -> 267.52776 | J36: =J30+SUM(J31:J35) -> 274.21595 | K36: =K30+SUM(K31:K35) -> 281.07135 | ... N36: =N30+SUM(N31:N35) -> 302.6831
B37: Venta al final del año 10 (neta de gastos) | C37: =SUM(D37:N37) -> 11010.077 | D37: =IF(D$25=10,PrecioVenta*(1+Revalorizacion)^10*(1-DescuentoNeg)*(1-ComisionVenta*(1+TipoIVA))-PlusvaliaSalida,0) -> 0 | E37: =IF(E$25=10,PrecioVenta*(1+Revalorizacion)^10*(1-DescuentoNeg)*(1-ComisionVenta*(1+TipoIVA))-PlusvaliaSalida,0) -> 0 | F37: =IF(F$25=10,PrecioVenta*(1+Revalorizacion)^10*(1-DescuentoNeg)*(1-ComisionVenta*(1+TipoIVA))-PlusvaliaSalida,0) -> 0 | G37: =IF(G$25=10,PrecioVenta*(1+Revalorizacion)^10*(1-DescuentoNeg)*(1-ComisionVenta*(1+TipoIVA))-PlusvaliaSalida,0) -> 0 | H37: =IF(H$25=10,PrecioVenta*(1+Revalorizacion)^10*(1-DescuentoNeg)*(1-ComisionVenta*(1+TipoIVA))-PlusvaliaSalida,0) -> 0 | I37: =IF(I$25=10,PrecioVenta*(1+Revalorizacion)^10*(1-DescuentoNeg)*(1-ComisionVenta*(1+TipoIVA))-PlusvaliaSalida,0) -> 0 | J37: =IF(J$25=10,PrecioVenta*(1+Revalorizacion)^10*(1-DescuentoNeg)*(1-ComisionVenta*(1+TipoIVA))-PlusvaliaSalida,0) -> 0 | K37: =IF(K$25=10,PrecioVenta*(1+Revalorizacion)^10*(1-DescuentoNeg)*(1-ComisionVenta*(1+TipoIVA))-PlusvaliaSalida,0) -> 0 | ... N37: =IF(N$25=10,PrecioVenta*(1+Revalorizacion)^10*(1-DescuentoNeg)*(1-ComisionVenta*(1+TipoIVA))-PlusvaliaSalida,0) -> 11010.077
B38: Flujo de caja | C38: =SUM(D38:N38) -> 6683.248 | D38: =D26+D36+D37 -> -7042.1582 | E38: =E26+E36+E37 -> 242.36694 | F38: =F26+F36+F37 -> 248.42612 | G38: =G26+G36+G37 -> 254.63677 | H38: =H26+H36+H37 -> 261.00269 | I38: =I26+I36+I37 -> 267.52776 | J38: =J26+J36+J37 -> 274.21595 | K38: =K26+K36+K37 -> 281.07135 | ... N38: =N26+N36+N37 -> 11312.76
B39: Caja acumulada | D39: =D38 -> -7042.1582 | E39: =D39+E38 -> -6799.7912 | F39: =E39+F38 -> -6551.3651 | G39: =F39+G38 -> -6296.7283 | H39: =G39+H38 -> -6035.7257 | I39: =H39+I38 -> -5768.1979 | J39: =I39+J38 -> -5493.9819 | K39: =J39+K38 -> -5212.9106 | L39: =K39+L38 -> -4924.8125 | ... N39: =M39+N38 -> 6683.248

Sheet Puja máxima
B2: Puja máxima y escalera de pujas
B3: Importe máximo que se puede ofrecer para alcanzar la rentabilidad objetivo, y resultado de cada nivel de puja.
B5: A. Puja máxima por estrategia
B6: Concepto | C6: Compraventa | D6: Alquiler
B7: Rentabilidad objetivo | C7: =ROIObjetivo -> 0.2 | D7: =RentabObjetivo -> 0.05 | E7: Cómo se calcula
B8: Ingreso neto por la venta / NOI año 1 | C8: =VentaNeta -> 9085.15 | D8: =NOIInicial -> 242.36694 | E8: • Compraventa: inversión máxima = ingreso neto por venta / (1 + ROI objetivo).
B9: Inversión total máxima admisible | C9: =C8/(1+C7) -> 7570.9583 | D9: =IF(D7>0,D8/D7,0) -> 4847.3388 | E9: • Alquiler: inversión máxima = NOI año 1 / rentabilidad neta objetivo.
B10: (−) Costes fijos de adquisición | C10: =-CostesFijosAdq -> -1020 | D10: =-CostesFijosAdq -> -1020 | E10: • Se restan los costes fijos y de tenencia; el resto se reparte entre puja e impuesto.
B11: (−) Coste de tenencia | C11: =-CosteTenenciaFlip -> -66.666667 | D11: =-CosteTenenciaAlq -> -26.666667 | E11: • Con ITP la base es el mayor entre la puja y el valor de referencia catastral.
B12: Disponible para puja + impuesto | C12: =SUM(C9:C11) -> 6484.2917 | D12: =SUM(D9:D11) -> 3800.6722 | E12: • Con IVA no deducible: puja máxima = disponible / (1 + 21%).
B13: Puja máxima | C13: =MAX(0,IF(Regimen=1,IF((C12)/(1+TipoITP)>=ValorReferencia,(C12)/(1+TipoITP),(C12)-TipoITP*ValorReferencia),(C12)/(1+TipoIVA*(1-IVADeducible)))) -> 5988.8002 | D13: =MAX(0,IF(Regimen=1,IF((D12)/(1+TipoITP)>=ValorReferencia,(D12)/(1+TipoITP),(D12)-TipoITP*ValorReferencia),(D12)/(1+TipoIVA*(1-IVADeducible)))) -> 3305.1807
B14: Puja máxima / valor de subasta | C14: =C13/ValorSubasta -> 0.84606095 | D14: =D13/ValorSubasta -> 0.46693565
B15: ¿Supera el umbral del 70%? | C15: =IF(C13>=UmbralSetenta,"Sí","No — riesgo art. 670.4 LEC") -> Sí | D15: =IF(D13>=UmbralSetenta,"Sí","No — riesgo art. 670.4 LEC") -> No — riesgo art. 670.4 LEC
B16: Puja de equilibrio (beneficio / rentabilidad 0) | C16: =MAX(0,IF(Regimen=1,IF((C8-CostesFijosAdq-CosteTenenciaFlip)/(1+TipoITP)>=ValorReferencia,(C8-CostesFijosAdq-CosteTenenciaFlip)/(1+TipoITP),(C8-CostesFijosAdq-CosteTenenciaFlip)-TipoITP*ValorReferencia),(C8-CostesFijosAdq-CosteTenenciaFlip)/(1+TipoIVA*(1-IVADeducible)))) -> 7475.2181
B18: Puja máxima recomendada (estrategia principal) | C18: =IF(Estrategia=1,PujaMaxFlip,PujaMaxAlq) -> 5988.8002
B19: Puja mínima prudente (umbral 70%, redondeado al euro superior) | C19: =ROUNDUP(UmbralSetenta,0) -> 4955
B21: B. Escalera de pujas
B22: % valor subasta | C22: Puja | D22: Régimen art. 670 LEC | E22: Impuesto adq. | F22: Inversión compraventa | G22: Beneficio antes imp. | H22: ROI compraventa | I22: ROI anualizado | J22: Beneficio neto | K22: Rentab. neta alquiler | L22: ¿Cumple objetivo?
B23: 0.4 | C23: =B23*ValorSubasta -> 2831.38 | D23: =IF(C23>=UmbralSetenta,"Aprobación directa (≥ 70%)",IF(C23>=UmbralCincuenta,"Mejorable por ejecutado/ejecutante","< 50%: decide el LAJ")) -> < 50%: decide el LAJ | E23: =IF(Regimen=1,TipoITP*MAX(C23,ValorReferencia),TipoIVA*C23*(1-IVADeducible)) -> 495.4915 | F23: =C23+E23+CostesFijosAdq+CosteTenenciaFlip -> 4413.5382 | G23: =VentaNeta-F23 -> 4671.6118 | H23: =IF(F23>0,G23/F23,0) -> 1.0584732 | I23: =IF(MesVenta>0,(1+H23)^(12/MesVenta)-1,0) -> 1.9533698 | J23: =G23-MAX(0,G23)*TipoGanancia -> 3784.0056 | K23: =NOIInicial/(C23+E23+CostesFijosAdq+CosteTenenciaAlq) -> 0.055416675 | L23: =IF(AND(C23>=UmbralSetenta,IF(Estrategia=1,H23>=ROIObjetivo,K23>=RentabObjetivo)),"Sí","No") -> No
B24: 0.45 | C24: =B24*ValorSubasta -> 3185.3025 | D24: =IF(C24>=UmbralSetenta,"Aprobación directa (≥ 70%)",IF(C24>=UmbralCincuenta,"Mejorable por ejecutado/ejecutante","< 50%: decide el LAJ")) -> < 50%: decide el LAJ | E24: =IF(Regimen=1,TipoITP*MAX(C24,ValorReferencia),TipoIVA*C24*(1-IVADeducible)) -> 495.4915 | F24: =C24+E24+CostesFijosAdq+CosteTenenciaFlip -> 4767.4607 | G24: =VentaNeta-F24 -> 4317.6893 | H24: =IF(F24>0,G24/F24,0) -> 0.90565809 | I24: =IF(MesVenta>0,(1+H24)^(12/MesVenta)-1,0) -> 1.6306767 | J24: =G24-MAX(0,G24)*TipoGanancia -> 3497.3284 | K24: =NOIInicial/(C24+E24+CostesFijosAdq+CosteTenenciaAlq) -> 0.051267892 | L24: =IF(AND(C24>=UmbralSetenta,IF(Estrategia=1,H24>=ROIObjetivo,K24>=RentabObjetivo)),"Sí","No") -> No
B25: 0.5 | C25: =B25*ValorSubasta -> 3539.225 | D25: =IF(C25>=UmbralSetenta,"Aprobación directa (≥ 70%)",IF(C25>=UmbralCincuenta,"Mejorable por ejecutado/ejecutante","< 50%: decide el LAJ")) -> Mejorable por ejecutado/ejecutante | E25: =IF(Regimen=1,TipoITP*MAX(C25,ValorReferencia),TipoIVA*C25*(1-IVADeducible)) -> 495.4915 | F25: =C25+E25+CostesFijosAdq+CosteTenenciaFlip -> 5121.3832 | G25: =VentaNeta-F25 -> 3963.7668 | H25: =IF(F25>0,G25/F25,0) -> 0.77396412 | I25: =IF(MesVenta>0,(1+H25)^(12/MesVenta)-1,0) -> 1.3627472 | J25: =G25-MAX(0,G25)*TipoGanancia -> 3210.6511 | K25: =NOIInicial/(C25+E25+CostesFijosAdq+CosteTenenciaAlq) -> 0.047697041 | L25: =IF(AND(C25>=UmbralSetenta,IF(Estrategia=1,H25>=ROIObjetivo,K25>=RentabObjetivo)),"Sí","No") -> No
B26: 0.55 | C26: =B26*ValorSubasta -> 3893.1475 | D26: =IF(C26>=UmbralSetenta,"Aprobación directa (≥ 70%)",IF(C26>=UmbralCincuenta,"Mejorable por ejecutado/ejecutante","< 50%: decide el LAJ")) -> Mejorable por ejecutado/ejecutante | E26: =IF(Regimen=1,TipoITP*MAX(C26,ValorReferencia),TipoIVA*C26*(1-IVADeducible)) -> 495.4915 | F26: =C26+E26+CostesFijosAdq+CosteTenenciaFlip -> 5475.3057 | G26: =VentaNeta-F26 -> 3609.8443 | H26: =IF(F26>0,G26/F26,0) -> 0.65929549 | I26: =IF(MesVenta>0,(1+H26)^(12/MesVenta)-1,0) -> 1.137399 | J26: =G26-MAX(0,G26)*TipoGanancia -> 2923.9739 | K26: =NOIInicial/(C26+E26+CostesFijosAdq+CosteTenenciaAlq) -> 0.044591226 | L26: =IF(AND(C26>=UmbralSetenta,IF(Estrategia=1,H26>=ROIObjetivo,K26>=RentabObjetivo)),"Sí","No") -> No
B27: 0.6 | C27: =B27*ValorSubasta -> 4247.07 | D27: =IF(C27>=UmbralSetenta,"Aprobación directa (≥ 70%)",IF(C27>=UmbralCincuenta,"Mejorable por ejecutado/ejecutante","< 50%: decide el LAJ")) -> Mejorable por ejecutado/ejecutante | E27: =IF(Regimen=1,TipoITP*MAX(C27,ValorReferencia),TipoIVA*C27*(1-IVADeducible)) -> 495.4915 | F27: =C27+E27+CostesFijosAdq+CosteTenenciaFlip -> 5829.2282 | G27: =VentaNeta-F27 -> 3255.9218 | H27: =IF(F27>0,G27/F27,0) -> 0.5585511 | I27: =IF(MesVenta>0,(1+H27)^(12/MesVenta)-1,0) -> 0.9457255 | J27: =G27-MAX(0,G27)*TipoGanancia -> 2637.2967 | K27: =NOIInicial/(C27+E27+CostesFijosAdq+CosteTenenciaAlq) -> 0.041865156 | L27: =IF(AND(C27>=UmbralSetenta,IF(Estrategia=1,H27>=ROIObjetivo,K27>=RentabObjetivo)),"Sí","No") -> No
B28: 0.65 | C28: =B28*ValorSubasta -> 4600.9925 | D28: =IF(C28>=UmbralSetenta,"Aprobación directa (≥ 70%)",IF(C28>=UmbralCincuenta,"Mejorable por ejecutado/ejecutante","< 50%: decide el LAJ")) -> Mejorable por ejecutado/ejecutante | E28: =IF(Regimen=1,TipoITP*MAX(C28,ValorReferencia),TipoIVA*C28*(1-IVADeducible)) -> 495.4915 | F28: =C28+E28+CostesFijosAdq+CosteTenenciaFlip -> 6183.1507 | G28: =VentaNeta-F28 -> 2901.9993 | H28: =IF(F28>0,G28/F28,0) -> 0.4693399 | I28: =IF(MesVenta>0,(1+H28)^(12/MesVenta)-1,0) -> 0.78107993 | J28: =G28-MAX(0,G28)*TipoGanancia -> 2350.6195 | K28: =NOIInicial/(C28+E28+CostesFijosAdq+CosteTenenciaAlq) -> 0.039453198 | L28: =IF(AND(C28>=UmbralSetenta,IF(Estrategia=1,H28>=ROIObjetivo,K28>=RentabObjetivo)),"Sí","No") -> No
B29: 0.7 | C29: =B29*ValorSubasta -> 4954.915 | D29: =IF(C29>=UmbralSetenta,"Aprobación directa (≥ 70%)",IF(C29>=UmbralCincuenta,"Mejorable por ejecutado/ejecutante","< 50%: decide el LAJ")) -> Aprobación directa (≥ 70%) | E29: =IF(Regimen=1,TipoITP*MAX(C29,ValorReferencia),TipoIVA*C29*(1-IVADeducible)) -> 495.4915 | F29: =C29+E29+CostesFijosAdq+CosteTenenciaFlip -> 6537.0732 | G29: =VentaNeta-F29 -> 2548.0768 | H29: =IF(F29>0,G29/F29,0) -> 0.38978864 | I29: =IF(MesVenta>0,(1+H29)^(12/MesVenta)-1,0) -> 0.63841205 | J29: =G29-MAX(0,G29)*TipoGanancia -> 2063.9422 | K29: =NOIInicial/(C29+E29+CostesFijosAdq+CosteTenenciaAlq) -> 0.037304019 | L29: =IF(AND(C29>=UmbralSetenta,IF(Estrategia=1,H29>=ROIObjetivo,K29>=RentabObjetivo)),"Sí","No") -> Sí
B30: 0.75 | C30: =B30*ValorSubasta -> 5308.8375 | D30: =IF(C30>=UmbralSetenta,"Aprobación directa (≥ 70%)",IF(C30>=UmbralCincuenta,"Mejorable por ejecutado/ejecutante","< 50%: decide el LAJ")) -> Aprobación directa (≥ 70%) | E30: =IF(Regimen=1,TipoITP*MAX(C30,ValorReferencia),TipoIVA*C30*(1-IVADeducible)) -> 495.4915 | F30: =C30+E30+CostesFijosAdq+CosteTenenciaFlip -> 6890.9957 | G30: =VentaNeta-F30 -> 2194.1543 | H30: =IF(F30>0,G30/F30,0) -> 0.3184089 | I30: =IF(MesVenta>0,(1+H30)^(12/MesVenta)-1,0) -> 0.51382331 | J30: =G30-MAX(0,G30)*TipoGanancia -> 1777.265 | K30: =NOIInicial/(C30+E30+CostesFijosAdq+CosteTenenciaAlq) -> 0.035376893 | L30: =IF(AND(C30>=UmbralSetenta,IF(Estrategia=1,H30>=ROIObjetivo,K30>=RentabObjetivo)),"Sí","No") -> Sí
B31: 0.8 | C31: =B31*ValorSubasta -> 5662.76 | D31: =IF(C31>=UmbralSetenta,"Aprobación directa (≥ 70%)",IF(C31>=UmbralCincuenta,"Mejorable por ejecutado/ejecutante","< 50%: decide el LAJ")) -> Aprobación directa (≥ 70%) | E31: =IF(Regimen=1,TipoITP*MAX(C31,ValorReferencia),TipoIVA*C31*(1-IVADeducible)) -> 495.4915 | F31: =C31+E31+CostesFijosAdq+CosteTenenciaFlip -> 7244.9182 | G31: =VentaNeta-F31 -> 1840.2318 | H31: =IF(F31>0,G31/F31,0) -> 0.25400312 | I31: =IF(MesVenta>0,(1+H31)^(12/MesVenta)-1,0) -> 0.4042613 | J31: =G31-MAX(0,G31)*TipoGanancia -> 1490.5878 | K31: =NOIInicial/(C31+E31+CostesFijosAdq+CosteTenenciaAlq) -> 0.033639097 | L31: =IF(AND(C31>=UmbralSetenta,IF(Estrategia=1,H31>=ROIObjetivo,K31>=RentabObjetivo)),"Sí","No") -> Sí
B32: 0.85 | C32: =B32*ValorSubasta -> 6016.6825 | D32: =IF(C32>=UmbralSetenta,"Aprobación directa (≥ 70%)",IF(C32>=UmbralCincuenta,"Mejorable por ejecutado/ejecutante","< 50%: decide el LAJ")) -> Aprobación directa (≥ 70%) | E32: =IF(Regimen=1,TipoITP*MAX(C32,ValorReferencia),TipoIVA*C32*(1-IVADeducible)) -> 495.4915 | F32: =C32+E32+CostesFijosAdq+CosteTenenciaFlip -> 7598.8407 | G32: =VentaNeta-F32 -> 1486.3093 | H32: =IF(F32>0,G32/F32,0) -> 0.19559685 | I32: =IF(MesVenta>0,(1+H32)^(12/MesVenta)-1,0) -> 0.30730567 | J32: =G32-MAX(0,G32)*TipoGanancia -> 1203.9106 | K32: =NOIInicial/(C32+E32+CostesFijosAdq+CosteTenenciaAlq) -> 0.032064036 | L32: =IF(AND(C32>=UmbralSetenta,IF(Estrategia=1,H32>=ROIObjetivo,K32>=RentabObjetivo)),"Sí","No") -> No
B33: 0.9 | C33: =B33*ValorSubasta -> 6370.605 | D33: =IF(C33>=UmbralSetenta,"Aprobación directa (≥ 70%)",IF(C33>=UmbralCincuenta,"Mejorable por ejecutado/ejecutante","< 50%: decide el LAJ")) -> Aprobación directa (≥ 70%) | E33: =IF(Regimen=1,TipoITP*MAX(C33,ValorReferencia),TipoIVA*C33*(1-IVADeducible)) -> 495.4915 | F33: =C33+E33+CostesFijosAdq+CosteTenenciaFlip -> 7952.7632 | G33: =VentaNeta-F33 -> 1132.3868 | H33: =IF(F33>0,G33/F33,0) -> 0.14238911 | I33: =IF(MesVenta>0,(1+H33)^(12/MesVenta)-1,0) -> 0.22101522 | J33: =G33-MAX(0,G33)*TipoGanancia -> 917.23334 | K33: =NOIInicial/(C33+E33+CostesFijosAdq+CosteTenenciaAlq) -> 0.030629874 | L33: =IF(AND(C33>=UmbralSetenta,IF(Estrategia=1,H33>=ROIObjetivo,K33>=RentabObjetivo)),"Sí","No") -> No
B34: 0.95 | C34: =B34*ValorSubasta -> 6724.5275 | D34: =IF(C34>=UmbralSetenta,"Aprobación directa (≥ 70%)",IF(C34>=UmbralCincuenta,"Mejorable por ejecutado/ejecutante","< 50%: decide el LAJ")) -> Aprobación directa (≥ 70%) | E34: =IF(Regimen=1,TipoITP*MAX(C34,ValorReferencia),TipoIVA*C34*(1-IVADeducible)) -> 495.4915 | F34: =C34+E34+CostesFijosAdq+CosteTenenciaFlip -> 8306.6857 | G34: =VentaNeta-F34 -> 778.46433 | H34: =IF(F34>0,G34/F34,0) -> 0.093715396 | I34: =IF(MesVenta>0,(1+H34)^(12/MesVenta)-1,0) -> 0.14381685 | J34: =G34-MAX(0,G34)*TipoGanancia -> 630.55611 | K34: =NOIInicial/(C34+E34+CostesFijosAdq+CosteTenenciaAlq) -> 0.029318514 | L34: =IF(AND(C34>=UmbralSetenta,IF(Estrategia=1,H34>=ROIObjetivo,K34>=RentabObjetivo)),"Sí","No") -> No
... B45: 1.5 | C45: =B45*ValorSubasta -> 10617.675 | D45: =IF(C45>=UmbralSetenta,"Aprobación directa (≥ 70%)",IF(C45>=UmbralCincuenta,"Mejorable por ejecutado/ejecutante","< 50%: decide el LAJ")) -> Aprobación directa (≥ 70%) | E45: =IF(Regimen=1,TipoITP*MAX(C45,ValorReferencia),TipoIVA*C45*(1-IVADeducible)) -> 743.23725 | F45: =C45+E45+CostesFijosAdq+CosteTenenciaFlip -> 12447.579 | G45: =VentaNeta-F45 -> -3362.4289 | H45: =IF(F45>0,G45/F45,0) -> -0.27012714 | I45: =IF(MesVenta>0,(1+H45)^(12/MesVenta)-1,0) -> -0.37645066 | J45: =G45-MAX(0,G45)*TipoGanancia -> -3362.4289 | K45: =NOIInicial/(C45+E45+CostesFijosAdq+CosteTenenciaAlq) -> 0.019533782 | L45: =IF(AND(C45>=UmbralSetenta,IF(Estrategia=1,H45>=ROIObjetivo,K45>=RentabObjetivo)),"Sí","No") -> No

Sheet Sensibilidad
B2: Análisis de sensibilidad
B3: Cada celda recalcula el resultado con fórmula cerrada; el resto de supuestos son los del escenario activo. Encabezados editables (azul).
B5: Caso activo — puja: | C5: =Puja -> 5500 | D5: precio de salida: | E5: =PrecioVenta -> 10000 | F5: renta: | G5: =Renta -> 45
B7: 1. Compraventa — beneficio antes de impuestos (€): puja × precio de salida
B8: Puja ↓ / Precio de salida → | C8: 7000 | D8: 8000 | E8: 9000 | F8: 10000 | G8: 11000 | H8: 12000 | I8: 13000
B9: 4000 | C9: =(C$8*(1-DescuentoNeg)*(1-ComisionVenta*(1+TipoIVA))-Plusvalia)-($B9+IF(Regimen=1,TipoITP*MAX($B9,ValorReferencia),TipoIVA*$B9*(1-IVADeducible))+CostesFijosAdq+CosteTenenciaFlip) -> 756.44683 | D9: =(D$8*(1-DescuentoNeg)*(1-ComisionVenta*(1+TipoIVA))-Plusvalia)-($B9+IF(Regimen=1,TipoITP*MAX($B9,ValorReferencia),TipoIVA*$B9*(1-IVADeducible))+CostesFijosAdq+CosteTenenciaFlip) -> 1671.9618 | E9: =(E$8*(1-DescuentoNeg)*(1-ComisionVenta*(1+TipoIVA))-Plusvalia)-($B9+IF(Regimen=1,TipoITP*MAX($B9,ValorReferencia),TipoIVA*$B9*(1-IVADeducible))+CostesFijosAdq+CosteTenenciaFlip) -> 2587.4768 | F9: =(F$8*(1-DescuentoNeg)*(1-ComisionVenta*(1+TipoIVA))-Plusvalia)-($B9+IF(Regimen=1,TipoITP*MAX($B9,ValorReferencia),TipoIVA*$B9*(1-IVADeducible))+CostesFijosAdq+CosteTenenciaFlip) -> 3502.9918 | G9: =(G$8*(1-DescuentoNeg)*(1-ComisionVenta*(1+TipoIVA))-Plusvalia)-($B9+IF(Regimen=1,TipoITP*MAX($B9,ValorReferencia),TipoIVA*$B9*(1-IVADeducible))+CostesFijosAdq+CosteTenenciaFlip) -> 4418.5068 | H9: =(H$8*(1-DescuentoNeg)*(1-ComisionVenta*(1+TipoIVA))-Plusvalia)-($B9+IF(Regimen=1,TipoITP*MAX($B9,ValorReferencia),TipoIVA*$B9*(1-IVADeducible))+CostesFijosAdq+CosteTenenciaFlip) -> 5334.0218 | I9: =(I$8*(1-DescuentoNeg)*(1-ComisionVenta*(1+TipoIVA))-Plusvalia)-($B9+IF(Regimen=1,TipoITP*MAX($B9,ValorReferencia),TipoIVA*$B9*(1-IVADeducible))+CostesFijosAdq+CosteTenenciaFlip) -> 6249.5368
B10: 4500 | C10: =(C$8*(1-DescuentoNeg)*(1-ComisionVenta*(1+TipoIVA))-Plusvalia)-($B10+IF(Regimen=1,TipoITP*MAX($B10,ValorReferencia),TipoIVA*$B10*(1-IVADeducible))+CostesFijosAdq+CosteTenenciaFlip) -> 256.44683 | D10: =(D$8*(1-DescuentoNeg)*(1-ComisionVenta*(1+TipoIVA))-Plusvalia)-($B10+IF(Regimen=1,TipoITP*MAX($B10,ValorReferencia),TipoIVA*$B10*(1-IVADeducible))+CostesFijosAdq+CosteTenenciaFlip) -> 1171.9618 | E10: =(E$8*(1-DescuentoNeg)*(1-ComisionVenta*(1+TipoIVA))-Plusvalia)-($B10+IF(Regimen=1,TipoITP*MAX($B10,ValorReferencia),TipoIVA*$B10*(1-IVADeducible))+CostesFijosAdq+CosteTenenciaFlip) -> 2087.4768 | F10: =(F$8*(1-DescuentoNeg)*(1-ComisionVenta*(1+TipoIVA))-Plusvalia)-($B10+IF(Regimen=1,TipoITP*MAX($B10,ValorReferencia),TipoIVA*$B10*(1-IVADeducible))+CostesFijosAdq+CosteTenenciaFlip) -> 3002.9918 | G10: =(G$8*(1-DescuentoNeg)*(1-ComisionVenta*(1+TipoIVA))-Plusvalia)-($B10+IF(Regimen=1,TipoITP*MAX($B10,ValorReferencia),TipoIVA*$B10*(1-IVADeducible))+CostesFijosAdq+CosteTenenciaFlip) -> 3918.5068 | H10: =(H$8*(1-DescuentoNeg)*(1-ComisionVenta*(1+TipoIVA))-Plusvalia)-($B10+IF(Regimen=1,TipoITP*MAX($B10,ValorReferencia),TipoIVA*$B10*(1-IVADeducible))+CostesFijosAdq+CosteTenenciaFlip) -> 4834.0218 | I10: =(I$8*(1-DescuentoNeg)*(1-ComisionVenta*(1+TipoIVA))-Plusvalia)-($B10+IF(Regimen=1,TipoITP*MAX($B10,ValorReferencia),TipoIVA*$B10*(1-IVADeducible))+CostesFijosAdq+CosteTenenciaFlip) -> 5749.5368
